[2024-06-18T07:27:22.545+0000] {local_task_job_runner.py:120} INFO - ::group::Pre task execution logs
[2024-06-18T07:27:22.560+0000] {taskinstance.py:2076} INFO - Dependencies all met for dep_context=non-requeueable deps ti=<TaskInstance: full_dbt_execute.run_dbt manual__2024-06-18T07:27:18.097403+00:00 [queued]>
[2024-06-18T07:27:22.569+0000] {taskinstance.py:2076} INFO - Dependencies all met for dep_context=requeueable deps ti=<TaskInstance: full_dbt_execute.run_dbt manual__2024-06-18T07:27:18.097403+00:00 [queued]>
[2024-06-18T07:27:22.570+0000] {taskinstance.py:2306} INFO - Starting attempt 1 of 1
[2024-06-18T07:27:22.589+0000] {taskinstance.py:2330} INFO - Executing <Task(DockerOperator): run_dbt> on 2024-06-18 07:27:18.097403+00:00
[2024-06-18T07:27:22.607+0000] {warnings.py:112} WARNING - /home/***/.local/lib/python3.12/site-packages/***/task/task_runner/standard_task_runner.py:61: DeprecationWarning: This process (pid=63) is multi-threaded, use of fork() may lead to deadlocks in the child.
  pid = os.fork()

[2024-06-18T07:27:22.610+0000] {standard_task_runner.py:63} INFO - Started process 65 to run task
[2024-06-18T07:27:22.612+0000] {standard_task_runner.py:90} INFO - Running: ['***', 'tasks', 'run', 'full_dbt_execute', 'run_dbt', 'manual__2024-06-18T07:27:18.097403+00:00', '--job-id', '218', '--raw', '--subdir', 'DAGS_FOLDER/full_dbt_execute.py', '--cfg-path', '/tmp/tmpdaat4v1h']
[2024-06-18T07:27:22.614+0000] {standard_task_runner.py:91} INFO - Job 218: Subtask run_dbt
[2024-06-18T07:27:22.651+0000] {task_command.py:426} INFO - Running <TaskInstance: full_dbt_execute.run_dbt manual__2024-06-18T07:27:18.097403+00:00 [running]> on host b1fbcf01fc69
[2024-06-18T07:27:22.692+0000] {taskinstance.py:2648} INFO - Exporting env vars: AIRFLOW_CTX_DAG_OWNER='***' AIRFLOW_CTX_DAG_ID='full_dbt_execute' AIRFLOW_CTX_TASK_ID='run_dbt' AIRFLOW_CTX_EXECUTION_DATE='2024-06-18T07:27:18.097403+00:00' AIRFLOW_CTX_TRY_NUMBER='1' AIRFLOW_CTX_DAG_RUN_ID='manual__2024-06-18T07:27:18.097403+00:00'
[2024-06-18T07:27:22.695+0000] {taskinstance.py:430} INFO - ::endgroup::
[2024-06-18T07:27:22.751+0000] {docker.py:366} INFO - Starting docker container from image custom_dbt_image
[2024-06-18T07:27:22.779+0000] {docker.py:374} WARNING - Using remote engine or docker-in-docker and mounting temporary volume from host is not supported. Falling back to `mount_tmp_dir=False` mode. You can set `mount_tmp_dir` parameter to False to disable mounting and remove the warning
[2024-06-18T07:27:25.198+0000] {docker.py:436} INFO - [0m07:27:25  Running with dbt=1.5.0
[2024-06-18T07:27:25.348+0000] {docker.py:436} INFO - [0m07:27:25  Unable to do partial parsing because of a version mismatch
[2024-06-18T07:27:26.064+0000] {docker.py:436} INFO - [0m07:27:26  Found 3 models, 4 tests, 0 snapshots, 0 analyses, 341 macros, 0 operations, 0 seed files, 2 sources, 0 exposures, 0 metrics, 0 groups
[2024-06-18T07:27:26.065+0000] {docker.py:436} INFO - [0m07:27:26
[2024-06-18T07:27:31.430+0000] {docker.py:436} INFO - [0m07:27:31  Concurrency: 1 threads (target='dev')
[2024-06-18T07:27:31.434+0000] {docker.py:436} INFO - [0m07:27:31
[2024-06-18T07:27:31.434+0000] {docker.py:436} INFO - [0m07:27:31  1 of 3 START sql table model mint.my_first_dbt_model ........................... [RUN]
[2024-06-18T07:27:31.542+0000] {docker.py:436} INFO - [0m07:27:31  1 of 3 OK created sql table model mint.my_first_dbt_model ...................... [[32mOK[0m in 0.11s]
[2024-06-18T07:27:31.542+0000] {docker.py:436} INFO - [0m07:27:31  2 of 3 START sql table model mint.stage_subscriptions .......................... [RUN]
[2024-06-18T07:27:31.620+0000] {docker.py:436} INFO - [0m07:27:31  2 of 3 ERROR creating sql table model mint.stage_subscriptions ................. [[31mERROR[0m in 0.08s]
[2024-06-18T07:27:31.621+0000] {docker.py:436} INFO - [0m07:27:31  3 of 3 START sql view model mint.my_second_dbt_model ........................... [RUN]
[2024-06-18T07:27:31.667+0000] {docker.py:436} INFO - [0m07:27:31  3 of 3 OK created sql view model mint.my_second_dbt_model ...................... [[32mOK[0m in 0.04s]
[2024-06-18T07:27:31.752+0000] {docker.py:436} INFO - [0m07:27:31
[2024-06-18T07:27:31.753+0000] {docker.py:436} INFO - [0m07:27:31  Finished running 2 table models, 1 view model in 0 hours 0 minutes and 5.69 seconds (5.69s).
[2024-06-18T07:27:31.772+0000] {docker.py:436} INFO - [0m07:27:31
[2024-06-18T07:27:31.774+0000] {docker.py:436} INFO - [0m07:27:31  [31mCompleted with 1 error and 0 warnings:[0m
[2024-06-18T07:27:31.775+0000] {docker.py:436} INFO - [0m07:27:31
[2024-06-18T07:27:31.776+0000] {docker.py:436} INFO - [0m07:27:31  [33mDatabase Error in model stage_subscriptions (models/example/stage_subscriptions.sql)[0m
[2024-06-18T07:27:31.778+0000] {docker.py:436} INFO - [0m07:27:31    Code: 497.
[2024-06-18T07:27:31.779+0000] {docker.py:436} INFO - [0m07:27:31    DB::Exception: ***: Not enough privileges. To execute this query, it's necessary to have the grant SELECT(_airbyte_unique_key, cancelled_at, updated_at, user_id, _ab_cdc_updated_at, created_at, _ab_cdc_deleted_at, _ab_cdc_lsn, id, plan_id, _airbyte_ab_id, _airbyte_emitted_at, _airbyte_normalized_at, _airbyte_subscriptions_hashid) ON analytics.subscriptions. Stack trace:
[2024-06-18T07:27:31.780+0000] {docker.py:436} INFO - [0m07:27:31
[2024-06-18T07:27:31.781+0000] {docker.py:436} INFO - [0m07:27:31    0. DB::Exception::Exception(DB::Exception::MessageMasked&&, int, bool) @ 0x000000000c01d464 in /usr/bin/clickhouse
[2024-06-18T07:27:31.781+0000] {docker.py:436} INFO - [0m07:27:31    1. DB::Exception::Exception<String, String>(int, FormatStringHelperImpl<std::type_identity<String>::type, std::type_identity<String>::type>, String&&, String&&) @ 0x00000000076c686c in /usr/bin/clickhouse
[2024-06-18T07:27:31.782+0000] {docker.py:436} INFO - [0m07:27:31    2. bool DB::ContextAccess::checkAccessImplHelper<true, false, std::basic_string_view<char, std::char_traits<char>>, std::basic_string_view<char, std::char_traits<char>>, std::vector<String, std::allocator<String>>>(DB::AccessFlags, std::basic_string_view<char, std::char_traits<char>> const&, std::basic_string_view<char, std::char_traits<char>> const&, std::vector<String, std::allocator<String>> const&) const @ 0x0000000010083ddc in /usr/bin/clickhouse
[2024-06-18T07:27:31.783+0000] {docker.py:436} INFO - [0m07:27:31    3. void DB::Context::checkAccessImpl<DB::AccessFlags, String, String, std::vector<String, std::allocator<String>>>(DB::AccessFlags const&, String const&, String const&, std::vector<String, std::allocator<String>> const&) const @ 0x000000001079010c in /usr/bin/clickhouse
[2024-06-18T07:27:31.785+0000] {docker.py:436} INFO - [0m07:27:31    4. DB::Context::checkAccess(DB::AccessFlags const&, DB::StorageID const&, std::vector<String, std::allocator<String>> const&) const @ 0x000000001078ff80 in /usr/bin/clickhouse
[2024-06-18T07:27:31.785+0000] {docker.py:436} INFO - [0m07:27:31    5. DB::InterpreterSelectQuery::InterpreterSelectQuery(std::shared_ptr<DB::IAST> const&, std::shared_ptr<DB::Context> const&, std::optional<DB::Pipe>, std::shared_ptr<DB::IStorage> const&, DB::SelectQueryOptions const&, std::vector<String, std::allocator<String>> const&, std::shared_ptr<DB::StorageInMemoryMetadata const> const&, std::shared_ptr<DB::PreparedSets>) @ 0x0000000010efa62c in /usr/bin/clickhouse
[2024-06-18T07:27:31.786+0000] {docker.py:436} INFO - [0m07:27:31    6. DB::InterpreterSelectWithUnionQuery::InterpreterSelectWithUnionQuery(std::shared_ptr<DB::IAST> const&, std::shared_ptr<DB::Context>, DB::SelectQueryOptions const&, std::vector<String, std::allocator<String>> const&) @ 0x0000000010f82164 in /usr/bin/clickhouse
[2024-06-18T07:27:31.786+0000] {docker.py:436} INFO - [0m07:27:31    7. DB::InterpreterSelectWithUnionQuery::getSampleBlock(std::shared_ptr<DB::IAST> const&, std::shared_ptr<DB::Context const>, bool, bool) @ 0x0000000010f84b90 in /usr/bin/clickhouse
[2024-06-18T07:27:31.787+0000] {docker.py:436} INFO - [0m07:27:31    8. DB::getDatabaseAndTablesWithColumns(std::vector<DB::ASTTableExpression const*, std::allocator<DB::ASTTableExpression const*>> const&, std::shared_ptr<DB::Context const>, bool, bool, bool) @ 0x0000000011273718 in /usr/bin/clickhouse
[2024-06-18T07:27:31.789+0000] {docker.py:436} INFO - [0m07:27:31    9. DB::JoinedTables::resolveTables() @ 0x0000000010fbb77c in /usr/bin/clickhouse
[2024-06-18T07:27:31.789+0000] {docker.py:436} INFO - [0m07:27:31    10. DB::InterpreterSelectQuery::InterpreterSelectQuery(std::shared_ptr<DB::IAST> const&, std::shared_ptr<DB::Context> const&, std::optional<DB::Pipe>, std::shared_ptr<DB::IStorage> const&, DB::SelectQueryOptions const&, std::vector<String, std::allocator<String>> const&, std::shared_ptr<DB::StorageInMemoryMetadata const> const&, std::shared_ptr<DB::PreparedSets>) @ 0x0000000010ef7a50 in /usr/bin/clickhouse
[2024-06-18T07:27:31.790+0000] {docker.py:436} INFO - [0m07:27:31    11. DB::InterpreterSelectWithUnionQuery::InterpreterSelectWithUnionQuery(std::shared_ptr<DB::IAST> const&, std::shared_ptr<DB::Context>, DB::SelectQueryOptions const&, std::vector<String, std::allocator<String>> const&) @ 0x0000000010f82164 in /usr/bin/clickhouse
[2024-06-18T07:27:31.791+0000] {docker.py:436} INFO - [0m07:27:31    12. DB::InterpreterSelectWithUnionQuery::getSampleBlock(std::shared_ptr<DB::IAST> const&, std::shared_ptr<DB::Context const>, bool, bool) @ 0x0000000010f84b90 in /usr/bin/clickhouse
[2024-06-18T07:27:31.791+0000] {docker.py:436} INFO - [0m07:27:31    13. DB::InterpreterCreateQuery::getTablePropertiesAndNormalizeCreateQuery(DB::ASTCreateQuery&) const @ 0x0000000010d59cc0 in /usr/bin/clickhouse
[2024-06-18T07:27:31.793+0000] {docker.py:436} INFO - [0m07:27:31    14. DB::InterpreterCreateQuery::createTable(DB::ASTCreateQuery&) @ 0x0000000010d5f5b4 in /usr/bin/clickhouse
[2024-06-18T07:27:31.794+0000] {docker.py:436} INFO - [0m07:27:31    15. DB::InterpreterCreateQuery::execute() @ 0x0000000010d6d220 in /usr/bin/clickhouse
[2024-06-18T07:27:31.795+0000] {docker.py:436} INFO - [0m07:27:31    16. DB::executeQueryImpl(char const*, char const*, std::shared_ptr<DB::Context>, bool, DB::QueryProcessingStage::Enum, DB::ReadBuffer*) @ 0x000000001126305c in /usr/bin/clickhouse
[2024-06-18T07:27:31.795+0000] {docker.py:436} INFO - [0m07:27:31    17. DB::executeQuery(String const&, std::shared_ptr<DB::Context>, bool, DB::QueryProcessingStage::Enum) @ 0x000000001125f86c in /usr/bin/clickhouse
[2024-06-18T07:27:31.795+0000] {docker.py:436} INFO - [0m07:27:31    18. DB::TCPHandler::runImpl() @ 0x0000000011ee42a4 in /usr/bin/clickhouse
[2024-06-18T07:27:31.797+0000] {docker.py:436} INFO - [0m07:27:31    19. DB::TCPHandler::run() @ 0x0000000011ef36a8 in /usr/bin/clickhouse
[2024-06-18T07:27:31.798+0000] {docker.py:436} INFO - [0m07:27:31    20. Poco::Net::TCPServerConnection::start() @ 0x000000001432d0e4 in /usr/bin/clickhouse
[2024-06-18T07:27:31.800+0000] {docker.py:436} INFO - [0m07:27:31    21. Poco::Net::TCPServerDispatcher::run() @ 0x000000001432e600 in /usr/bin/clickhouse
[2024-06-18T07:27:31.802+0000] {docker.py:436} INFO - [0m07:27:31    22. Poco::PooledThread::run() @ 0x000000001446dcfc in /usr/bin/clickhouse
[2024-06-18T07:27:31.803+0000] {docker.py:436} INFO - [0m07:27:31    23. Poco::ThreadImpl::runnableEntry(void*) @ 0x000000001446bea4 in /usr/bin/clickhouse
[2024-06-18T07:27:31.804+0000] {docker.py:436} INFO - [0m07:27:31    24. start_thread @ 0x0000000000007624 in /usr/lib/aarch64-linux-gnu/libpthread-2.31.so
[2024-06-18T07:27:31.804+0000] {docker.py:436} INFO - [0m07:27:31    25. ? @ 0x00000000000d149c in /usr/lib/aarch64-linux-gnu/libc-2.31.so
[2024-06-18T07:27:31.806+0000] {docker.py:436} INFO - [0m07:27:31
[2024-06-18T07:27:31.806+0000] {docker.py:436} INFO - [0m07:27:31  Done. PASS=2 WARN=0 ERROR=1 SKIP=0 TOTAL=3
[2024-06-18T07:27:32.664+0000] {taskinstance.py:441} INFO - ::group::Post task execution logs
[2024-06-18T07:27:32.689+0000] {taskinstance.py:2905} ERROR - Task failed with exception
Traceback (most recent call last):
  File "/home/airflow/.local/lib/python3.12/site-packages/docker/api/client.py", line 275, in _raise_for_status
    response.raise_for_status()
  File "/home/airflow/.local/lib/python3.12/site-packages/requests/models.py", line 1021, in raise_for_status
    raise HTTPError(http_error_msg, response=self)
requests.exceptions.HTTPError: 400 Client Error: Bad Request for url: http+docker://localhost/v1.45/containers/create

The above exception was the direct cause of the following exception:

Traceback (most recent call last):
  File "/home/airflow/.local/lib/python3.12/site-packages/airflow/providers/docker/operators/docker.py", line 371, in _run_image
    return self._run_image_with_mounts([*self.mounts, tmp_mount], add_tmp_variable=True)
           ^^^^^^^^^^^^^^^^^^^^^^^^^^^^^^^^^^^^^^^^^^^^^^^^^^^^^^^^^^^^^^^^^^^^^^^^^^^^^
  File "/home/airflow/.local/lib/python3.12/site-packages/airflow/providers/docker/operators/docker.py", line 398, in _run_image_with_mounts
    self.container = self.cli.create_container(
                     ^^^^^^^^^^^^^^^^^^^^^^^^^^
  File "/home/airflow/.local/lib/python3.12/site-packages/docker/api/container.py", line 440, in create_container
    return self.create_container_from_config(config, name, platform)
           ^^^^^^^^^^^^^^^^^^^^^^^^^^^^^^^^^^^^^^^^^^^^^^^^^^^^^^^^^
  File "/home/airflow/.local/lib/python3.12/site-packages/docker/api/container.py", line 457, in create_container_from_config
    return self._result(res, True)
           ^^^^^^^^^^^^^^^^^^^^^^^
  File "/home/airflow/.local/lib/python3.12/site-packages/docker/api/client.py", line 281, in _result
    self._raise_for_status(response)
  File "/home/airflow/.local/lib/python3.12/site-packages/docker/api/client.py", line 277, in _raise_for_status
    raise create_api_error_from_http_exception(e) from e
          ^^^^^^^^^^^^^^^^^^^^^^^^^^^^^^^^^^^^^^^
  File "/home/airflow/.local/lib/python3.12/site-packages/docker/errors.py", line 39, in create_api_error_from_http_exception
    raise cls(e, response=response, explanation=explanation) from e
docker.errors.APIError: 400 Client Error for http+docker://localhost/v1.45/containers/create: Bad Request ("invalid mount config for type "bind": bind source path does not exist: /host_mnt/private/tmp/airflowtmp6b2quh5h")

During handling of the above exception, another exception occurred:

Traceback (most recent call last):
  File "/home/airflow/.local/lib/python3.12/site-packages/airflow/models/taskinstance.py", line 465, in _execute_task
    result = _execute_callable(context=context, **execute_callable_kwargs)
             ^^^^^^^^^^^^^^^^^^^^^^^^^^^^^^^^^^^^^^^^^^^^^^^^^^^^^^^^^^^^^
  File "/home/airflow/.local/lib/python3.12/site-packages/airflow/models/taskinstance.py", line 432, in _execute_callable
    return execute_callable(context=context, **execute_callable_kwargs)
           ^^^^^^^^^^^^^^^^^^^^^^^^^^^^^^^^^^^^^^^^^^^^^^^^^^^^^^^^^^^^
  File "/home/airflow/.local/lib/python3.12/site-packages/airflow/models/baseoperator.py", line 401, in wrapper
    return func(self, *args, **kwargs)
           ^^^^^^^^^^^^^^^^^^^^^^^^^^^
  File "/home/airflow/.local/lib/python3.12/site-packages/airflow/providers/docker/operators/docker.py", line 509, in execute
    return self._run_image()
           ^^^^^^^^^^^^^^^^^
  File "/home/airflow/.local/lib/python3.12/site-packages/airflow/providers/docker/operators/docker.py", line 380, in _run_image
    return self._run_image_with_mounts(self.mounts, add_tmp_variable=False)
           ^^^^^^^^^^^^^^^^^^^^^^^^^^^^^^^^^^^^^^^^^^^^^^^^^^^^^^^^^^^^^^^^
  File "/home/airflow/.local/lib/python3.12/site-packages/airflow/providers/docker/operators/docker.py", line 444, in _run_image_with_mounts
    raise DockerContainerFailedException(f"Docker container failed: {result!r}", logs=log_lines)
airflow.providers.docker.exceptions.DockerContainerFailedException: Docker container failed: {'StatusCode': 1}
[2024-06-18T07:27:32.714+0000] {taskinstance.py:1206} INFO - Marking task as FAILED. dag_id=full_dbt_execute, task_id=run_dbt, run_id=manual__2024-06-18T07:27:18.097403+00:00, execution_date=20240618T072718, start_date=20240618T072722, end_date=20240618T072732
[2024-06-18T07:27:32.730+0000] {standard_task_runner.py:110} ERROR - Failed to execute job 218 for task run_dbt (Docker container failed: {'StatusCode': 1}; 65)
[2024-06-18T07:27:32.760+0000] {local_task_job_runner.py:240} INFO - Task exited with return code 1
[2024-06-18T07:27:32.815+0000] {taskinstance.py:3503} INFO - 0 downstream tasks scheduled from follow-on schedule check
[2024-06-18T07:27:32.822+0000] {local_task_job_runner.py:222} INFO - ::endgroup::
