[2024-06-17T16:26:48.988+0000] {local_task_job_runner.py:120} INFO - ::group::Pre task execution logs
[2024-06-17T16:26:49.002+0000] {taskinstance.py:2076} INFO - Dependencies all met for dep_context=non-requeueable deps ti=<TaskInstance: full_dbt_execute.run_dbt manual__2024-06-17T16:26:47.758939+00:00 [queued]>
[2024-06-17T16:26:49.007+0000] {taskinstance.py:2076} INFO - Dependencies all met for dep_context=requeueable deps ti=<TaskInstance: full_dbt_execute.run_dbt manual__2024-06-17T16:26:47.758939+00:00 [queued]>
[2024-06-17T16:26:49.007+0000] {taskinstance.py:2306} INFO - Starting attempt 1 of 1
[2024-06-17T16:26:49.014+0000] {taskinstance.py:2330} INFO - Executing <Task(DockerOperator): run_dbt> on 2024-06-17 16:26:47.758939+00:00
[2024-06-17T16:26:49.023+0000] {warnings.py:112} WARNING - /home/***/.local/lib/python3.12/site-packages/***/task/task_runner/standard_task_runner.py:61: DeprecationWarning: This process (pid=126) is multi-threaded, use of fork() may lead to deadlocks in the child.
  pid = os.fork()

[2024-06-17T16:26:49.024+0000] {standard_task_runner.py:63} INFO - Started process 128 to run task
[2024-06-17T16:26:49.024+0000] {standard_task_runner.py:90} INFO - Running: ['***', 'tasks', 'run', 'full_dbt_execute', 'run_dbt', 'manual__2024-06-17T16:26:47.758939+00:00', '--job-id', '203', '--raw', '--subdir', 'DAGS_FOLDER/full_dbt_execute.py', '--cfg-path', '/tmp/tmphcibvgen']
[2024-06-17T16:26:49.026+0000] {standard_task_runner.py:91} INFO - Job 203: Subtask run_dbt
[2024-06-17T16:26:49.052+0000] {task_command.py:426} INFO - Running <TaskInstance: full_dbt_execute.run_dbt manual__2024-06-17T16:26:47.758939+00:00 [running]> on host a1b8253dd4b8
[2024-06-17T16:26:49.118+0000] {taskinstance.py:2648} INFO - Exporting env vars: AIRFLOW_CTX_DAG_OWNER='***' AIRFLOW_CTX_DAG_ID='full_dbt_execute' AIRFLOW_CTX_TASK_ID='run_dbt' AIRFLOW_CTX_EXECUTION_DATE='2024-06-17T16:26:47.758939+00:00' AIRFLOW_CTX_TRY_NUMBER='1' AIRFLOW_CTX_DAG_RUN_ID='manual__2024-06-17T16:26:47.758939+00:00'
[2024-06-17T16:26:49.120+0000] {taskinstance.py:430} INFO - ::endgroup::
[2024-06-17T16:26:49.179+0000] {docker.py:366} INFO - Starting docker container from image custom_dbt_image
[2024-06-17T16:26:49.187+0000] {docker.py:374} WARNING - Using remote engine or docker-in-docker and mounting temporary volume from host is not supported. Falling back to `mount_tmp_dir=False` mode. You can set `mount_tmp_dir` parameter to False to disable mounting and remove the warning
[2024-06-17T16:26:51.764+0000] {docker.py:436} INFO - [0m16:26:51  Running with dbt=1.5.0
[2024-06-17T16:26:52.045+0000] {docker.py:436} INFO - [0m16:26:52  Found 2 models, 4 tests, 0 snapshots, 0 analyses, 341 macros, 0 operations, 0 seed files, 0 sources, 0 exposures, 0 metrics, 0 groups
[2024-06-17T16:26:52.046+0000] {docker.py:436} INFO - [0m16:26:52
[2024-06-17T16:26:52.535+0000] {docker.py:436} INFO - Failed to connect to warehouse:9000
Traceback (most recent call last):
  File "/usr/local/lib/python3.7/dist-packages/clickhouse_driver/connection.py", line 396, in connect
    return self._init_connection(host, port)
  File "/usr/local/lib/python3.7/dist-packages/clickhouse_driver/connection.py", line 326, in _init_connection
    self.socket = self._create_socket(host, port)
  File "/usr/local/lib/python3.7/dist-packages/clickhouse_driver/connection.py", line 276, in _create_socket
    for res in socket.getaddrinfo(host, port, 0, socket.SOCK_STREAM):
  File "/usr/lib/python3.7/socket.py", line 748, in getaddrinfo
    for res in _socket.getaddrinfo(host, port, family, type, proto, flags):
socket.gaierror: [Errno -2] Name or service not known
[2024-06-17T16:26:58.583+0000] {docker.py:436} INFO - Failed to connect to warehouse:9000
Traceback (most recent call last):
  File "/usr/local/lib/python3.7/dist-packages/dbt/adapters/clickhouse/nativeclient.py", line 72, in _create_client
    client.connection.connect()
  File "/usr/local/lib/python3.7/dist-packages/clickhouse_driver/connection.py", line 417, in connect
    raise err
clickhouse_driver.errors.NetworkError: Code: 210. Name or service not known (warehouse:9000)

The above exception was the direct cause of the following exception:

Traceback (most recent call last):
  File "/usr/local/lib/python3.7/dist-packages/dbt/adapters/base/connections.py", line 241, in retry_connection
    connection.handle = connect()
  File "/usr/local/lib/python3.7/dist-packages/dbt/adapters/clickhouse/connections.py", line 43, in connect
    return get_db_client(credentials)
  File "/usr/local/lib/python3.7/dist-packages/dbt/adapters/clickhouse/dbclient.py", line 38, in get_db_client
    return ChNativeClient(credentials)
  File "/usr/local/lib/python3.7/dist-packages/dbt/adapters/clickhouse/dbclient.py", line 70, in __init__
    self._client = self._create_client(credentials)
  File "/usr/local/lib/python3.7/dist-packages/dbt/adapters/clickhouse/nativeclient.py", line 74, in _create_client
    raise ChRetryableException(str(ex)) from ex
dbt.adapters.clickhouse.dbclient.ChRetryableException: Code: 210. Name or service not known (warehouse:9000)

During handling of the above exception, another exception occurred:

Traceback (most recent call last):
  File "/usr/local/lib/python3.7/dist-packages/clickhouse_driver/connection.py", line 396, in connect
    return self._init_connection(host, port)
  File "/usr/local/lib/python3.7/dist-packages/clickhouse_driver/connection.py", line 326, in _init_connection
    self.socket = self._create_socket(host, port)
  File "/usr/local/lib/python3.7/dist-packages/clickhouse_driver/connection.py", line 276, in _create_socket
    for res in socket.getaddrinfo(host, port, 0, socket.SOCK_STREAM):
  File "/usr/lib/python3.7/socket.py", line 748, in getaddrinfo
    for res in _socket.getaddrinfo(host, port, family, type, proto, flags):
socket.gaierror: [Errno -2] Name or service not known
[2024-06-17T16:26:58.601+0000] {docker.py:436} INFO - [0m16:26:58
[2024-06-17T16:26:58.601+0000] {docker.py:436} INFO - [0m16:26:58  Finished running  in 0 hours 0 minutes and 6.55 seconds (6.55s).
[2024-06-17T16:26:58.602+0000] {docker.py:436} INFO - [0m16:26:58  Encountered an error:
Database Error
  Code: 210. Name or service not known (warehouse:9000)
[2024-06-17T16:27:00.295+0000] {taskinstance.py:441} INFO - ::group::Post task execution logs
[2024-06-17T16:27:00.328+0000] {taskinstance.py:2905} ERROR - Task failed with exception
Traceback (most recent call last):
  File "/home/airflow/.local/lib/python3.12/site-packages/docker/api/client.py", line 275, in _raise_for_status
    response.raise_for_status()
  File "/home/airflow/.local/lib/python3.12/site-packages/requests/models.py", line 1021, in raise_for_status
    raise HTTPError(http_error_msg, response=self)
requests.exceptions.HTTPError: 400 Client Error: Bad Request for url: http+docker://localhost/v1.45/containers/create

The above exception was the direct cause of the following exception:

Traceback (most recent call last):
  File "/home/airflow/.local/lib/python3.12/site-packages/airflow/providers/docker/operators/docker.py", line 371, in _run_image
    return self._run_image_with_mounts([*self.mounts, tmp_mount], add_tmp_variable=True)
           ^^^^^^^^^^^^^^^^^^^^^^^^^^^^^^^^^^^^^^^^^^^^^^^^^^^^^^^^^^^^^^^^^^^^^^^^^^^^^
  File "/home/airflow/.local/lib/python3.12/site-packages/airflow/providers/docker/operators/docker.py", line 398, in _run_image_with_mounts
    self.container = self.cli.create_container(
                     ^^^^^^^^^^^^^^^^^^^^^^^^^^
  File "/home/airflow/.local/lib/python3.12/site-packages/docker/api/container.py", line 440, in create_container
    return self.create_container_from_config(config, name, platform)
           ^^^^^^^^^^^^^^^^^^^^^^^^^^^^^^^^^^^^^^^^^^^^^^^^^^^^^^^^^
  File "/home/airflow/.local/lib/python3.12/site-packages/docker/api/container.py", line 457, in create_container_from_config
    return self._result(res, True)
           ^^^^^^^^^^^^^^^^^^^^^^^
  File "/home/airflow/.local/lib/python3.12/site-packages/docker/api/client.py", line 281, in _result
    self._raise_for_status(response)
  File "/home/airflow/.local/lib/python3.12/site-packages/docker/api/client.py", line 277, in _raise_for_status
    raise create_api_error_from_http_exception(e) from e
          ^^^^^^^^^^^^^^^^^^^^^^^^^^^^^^^^^^^^^^^
  File "/home/airflow/.local/lib/python3.12/site-packages/docker/errors.py", line 39, in create_api_error_from_http_exception
    raise cls(e, response=response, explanation=explanation) from e
docker.errors.APIError: 400 Client Error for http+docker://localhost/v1.45/containers/create: Bad Request ("invalid mount config for type "bind": bind source path does not exist: /host_mnt/private/tmp/airflowtmpbhkui09s")

During handling of the above exception, another exception occurred:

Traceback (most recent call last):
  File "/home/airflow/.local/lib/python3.12/site-packages/airflow/models/taskinstance.py", line 465, in _execute_task
    result = _execute_callable(context=context, **execute_callable_kwargs)
             ^^^^^^^^^^^^^^^^^^^^^^^^^^^^^^^^^^^^^^^^^^^^^^^^^^^^^^^^^^^^^
  File "/home/airflow/.local/lib/python3.12/site-packages/airflow/models/taskinstance.py", line 432, in _execute_callable
    return execute_callable(context=context, **execute_callable_kwargs)
           ^^^^^^^^^^^^^^^^^^^^^^^^^^^^^^^^^^^^^^^^^^^^^^^^^^^^^^^^^^^^
  File "/home/airflow/.local/lib/python3.12/site-packages/airflow/models/baseoperator.py", line 401, in wrapper
    return func(self, *args, **kwargs)
           ^^^^^^^^^^^^^^^^^^^^^^^^^^^
  File "/home/airflow/.local/lib/python3.12/site-packages/airflow/providers/docker/operators/docker.py", line 509, in execute
    return self._run_image()
           ^^^^^^^^^^^^^^^^^
  File "/home/airflow/.local/lib/python3.12/site-packages/airflow/providers/docker/operators/docker.py", line 380, in _run_image
    return self._run_image_with_mounts(self.mounts, add_tmp_variable=False)
           ^^^^^^^^^^^^^^^^^^^^^^^^^^^^^^^^^^^^^^^^^^^^^^^^^^^^^^^^^^^^^^^^
  File "/home/airflow/.local/lib/python3.12/site-packages/airflow/providers/docker/operators/docker.py", line 444, in _run_image_with_mounts
    raise DockerContainerFailedException(f"Docker container failed: {result!r}", logs=log_lines)
airflow.providers.docker.exceptions.DockerContainerFailedException: Docker container failed: {'StatusCode': 2}
[2024-06-17T16:27:00.335+0000] {taskinstance.py:1206} INFO - Marking task as FAILED. dag_id=full_dbt_execute, task_id=run_dbt, run_id=manual__2024-06-17T16:26:47.758939+00:00, execution_date=20240617T162647, start_date=20240617T162649, end_date=20240617T162700
[2024-06-17T16:27:00.348+0000] {standard_task_runner.py:110} ERROR - Failed to execute job 203 for task run_dbt (Docker container failed: {'StatusCode': 2}; 128)
[2024-06-17T16:27:00.365+0000] {local_task_job_runner.py:240} INFO - Task exited with return code 1
[2024-06-17T16:27:00.411+0000] {taskinstance.py:3503} INFO - 0 downstream tasks scheduled from follow-on schedule check
[2024-06-17T16:27:00.414+0000] {local_task_job_runner.py:222} INFO - ::endgroup::
