[2024-06-16T12:09:21.982+0000] {local_task_job_runner.py:120} INFO - ::group::Pre task execution logs
[2024-06-16T12:09:21.995+0000] {taskinstance.py:2076} INFO - Dependencies all met for dep_context=non-requeueable deps ti=<TaskInstance: full_dbt_execute.run_dbt manual__2024-06-16T12:09:19.592679+00:00 [queued]>
[2024-06-16T12:09:21.999+0000] {taskinstance.py:2076} INFO - Dependencies all met for dep_context=requeueable deps ti=<TaskInstance: full_dbt_execute.run_dbt manual__2024-06-16T12:09:19.592679+00:00 [queued]>
[2024-06-16T12:09:21.999+0000] {taskinstance.py:2306} INFO - Starting attempt 1 of 1
[2024-06-16T12:09:22.005+0000] {taskinstance.py:2330} INFO - Executing <Task(DockerOperator): run_dbt> on 2024-06-16 12:09:19.592679+00:00
[2024-06-16T12:09:22.009+0000] {warnings.py:112} WARNING - /home/***/.local/lib/python3.12/site-packages/***/task/task_runner/standard_task_runner.py:61: DeprecationWarning: This process (pid=69) is multi-threaded, use of fork() may lead to deadlocks in the child.
  pid = os.fork()

[2024-06-16T12:09:22.009+0000] {standard_task_runner.py:63} INFO - Started process 71 to run task
[2024-06-16T12:09:22.009+0000] {standard_task_runner.py:90} INFO - Running: ['***', 'tasks', 'run', 'full_dbt_execute', 'run_dbt', 'manual__2024-06-16T12:09:19.592679+00:00', '--job-id', '178', '--raw', '--subdir', 'DAGS_FOLDER/full_dbt_execute.py', '--cfg-path', '/tmp/tmpbgb9h5f8']
[2024-06-16T12:09:22.010+0000] {standard_task_runner.py:91} INFO - Job 178: Subtask run_dbt
[2024-06-16T12:09:22.035+0000] {task_command.py:426} INFO - Running <TaskInstance: full_dbt_execute.run_dbt manual__2024-06-16T12:09:19.592679+00:00 [running]> on host a1b8253dd4b8
[2024-06-16T12:09:22.085+0000] {taskinstance.py:2648} INFO - Exporting env vars: AIRFLOW_CTX_DAG_OWNER='***' AIRFLOW_CTX_DAG_ID='full_dbt_execute' AIRFLOW_CTX_TASK_ID='run_dbt' AIRFLOW_CTX_EXECUTION_DATE='2024-06-16T12:09:19.592679+00:00' AIRFLOW_CTX_TRY_NUMBER='1' AIRFLOW_CTX_DAG_RUN_ID='manual__2024-06-16T12:09:19.592679+00:00'
[2024-06-16T12:09:22.087+0000] {taskinstance.py:430} INFO - ::endgroup::
[2024-06-16T12:09:22.140+0000] {docker.py:366} INFO - Starting docker container from image custom_dbt_image
[2024-06-16T12:09:22.162+0000] {docker.py:374} WARNING - Using remote engine or docker-in-docker and mounting temporary volume from host is not supported. Falling back to `mount_tmp_dir=False` mode. You can set `mount_tmp_dir` parameter to False to disable mounting and remove the warning
[2024-06-16T12:09:24.006+0000] {docker.py:436} INFO - [0m12:09:24  Running with dbt=1.5.0
[2024-06-16T12:09:24.104+0000] {docker.py:436} INFO - [0m12:09:24  Unable to do partial parsing because of a version mismatch
[2024-06-16T12:09:24.856+0000] {docker.py:436} INFO - [0m12:09:24  Found 2 models, 4 tests, 0 snapshots, 0 analyses, 341 macros, 0 operations, 0 seed files, 0 sources, 0 exposures, 0 metrics, 0 groups
[2024-06-16T12:09:24.858+0000] {docker.py:436} INFO - [0m12:09:24
[2024-06-16T12:09:30.170+0000] {docker.py:436} INFO - [0m12:09:30  dbt_clickhouse adapter: ClickHouse server does not support the EXCHANGE TABLES command
[2024-06-16T12:09:30.172+0000] {docker.py:436} INFO - [0m12:09:30  dbt_clickhouse adapter: This can be caused by an obsolete ClickHouse version or by running ClickHouse on
[2024-06-16T12:09:30.173+0000] {docker.py:436} INFO - [0m12:09:30  dbt_clickhouse adapter: an operating system that does not support the low level renameat2() system call.
[2024-06-16T12:09:30.173+0000] {docker.py:436} INFO - [0m12:09:30  dbt_clickhouse adapter: Some DBT materializations will be slower and not atomic as a result.
[2024-06-16T12:09:30.176+0000] {docker.py:436} INFO - [0m12:09:30  dbt_clickhouse adapter: Unexpected server exception dropping table
[2024-06-16T12:09:30.200+0000] {docker.py:436} INFO - [0m12:09:30  dbt_clickhouse adapter: ClickHouse server does not support the EXCHANGE TABLES command
[2024-06-16T12:09:30.200+0000] {docker.py:436} INFO - [0m12:09:30  dbt_clickhouse adapter: This can be caused by an obsolete ClickHouse version or by running ClickHouse on
[2024-06-16T12:09:30.201+0000] {docker.py:436} INFO - [0m12:09:30  dbt_clickhouse adapter: an operating system that does not support the low level renameat2() system call.
[2024-06-16T12:09:30.201+0000] {docker.py:436} INFO - [0m12:09:30  dbt_clickhouse adapter: Some DBT materializations will be slower and not atomic as a result.
[2024-06-16T12:09:30.203+0000] {docker.py:436} INFO - [0m12:09:30  dbt_clickhouse adapter: Unexpected server exception dropping table
[2024-06-16T12:09:35.255+0000] {docker.py:436} INFO - [0m12:09:35  Concurrency: 1 threads (target='dev')
[2024-06-16T12:09:35.256+0000] {docker.py:436} INFO - [0m12:09:35
[2024-06-16T12:09:35.265+0000] {docker.py:436} INFO - [0m12:09:35  1 of 2 START sql table model mint.my_first_dbt_model ........................... [RUN]
[2024-06-16T12:09:35.339+0000] {docker.py:436} INFO - [0m12:09:35  1 of 2 ERROR creating sql table model mint.my_first_dbt_model .................. [[31mERROR[0m in 0.07s]
[2024-06-16T12:09:35.341+0000] {docker.py:436} INFO - [0m12:09:35  2 of 2 SKIP relation mint.my_second_dbt_model .................................. [[33mSKIP[0m]
[2024-06-16T12:09:35.365+0000] {docker.py:436} INFO - [0m12:09:35
[2024-06-16T12:09:35.365+0000] {docker.py:436} INFO - [0m12:09:35  Finished running 1 table model, 1 view model in 0 hours 0 minutes and 10.51 seconds (10.51s).
[2024-06-16T12:09:35.373+0000] {docker.py:436} INFO - [0m12:09:35
[2024-06-16T12:09:35.373+0000] {docker.py:436} INFO - [0m12:09:35  [31mCompleted with 1 error and 0 warnings:[0m
[2024-06-16T12:09:35.373+0000] {docker.py:436} INFO - [0m12:09:35
[2024-06-16T12:09:35.374+0000] {docker.py:436} INFO - [0m12:09:35  [33mDatabase Error in model my_first_dbt_model (models/example/my_first_dbt_model.sql)[0m
[2024-06-16T12:09:35.374+0000] {docker.py:436} INFO - [0m12:09:35    Code: 497.
[2024-06-16T12:09:35.375+0000] {docker.py:436} INFO - [0m12:09:35    DB::Exception: ***: Not enough privileges. To execute this query, it's necessary to have the grant INSERT(id) ON mint.my_first_dbt_model. Stack trace:
[2024-06-16T12:09:35.375+0000] {docker.py:436} INFO - [0m12:09:35
[2024-06-16T12:09:35.375+0000] {docker.py:436} INFO - [0m12:09:35    0. DB::Exception::Exception(DB::Exception::MessageMasked&&, int, bool) @ 0x000000000c01d464 in /usr/bin/clickhouse
[2024-06-16T12:09:35.376+0000] {docker.py:436} INFO - [0m12:09:35    1. DB::Exception::Exception<String, String>(int, FormatStringHelperImpl<std::type_identity<String>::type, std::type_identity<String>::type>, String&&, String&&) @ 0x00000000076c686c in /usr/bin/clickhouse
[2024-06-16T12:09:35.376+0000] {docker.py:436} INFO - [0m12:09:35    2. bool DB::ContextAccess::checkAccessImplHelper<true, false, std::basic_string_view<char, std::char_traits<char>>, std::basic_string_view<char, std::char_traits<char>>, std::vector<String, std::allocator<String>>>(DB::AccessFlags, std::basic_string_view<char, std::char_traits<char>> const&, std::basic_string_view<char, std::char_traits<char>> const&, std::vector<String, std::allocator<String>> const&) const @ 0x0000000010083ddc in /usr/bin/clickhouse
[2024-06-16T12:09:35.376+0000] {docker.py:436} INFO - [0m12:09:35    3. void DB::Context::checkAccessImpl<DB::AccessFlags, String, String, std::vector<String, std::allocator<String>>>(DB::AccessFlags const&, String const&, String const&, std::vector<String, std::allocator<String>> const&) const @ 0x000000001079010c in /usr/bin/clickhouse
[2024-06-16T12:09:35.377+0000] {docker.py:436} INFO - [0m12:09:35    4. DB::Context::checkAccess(DB::AccessFlags const&, DB::StorageID const&, std::vector<String, std::allocator<String>> const&) const @ 0x000000001078ff80 in /usr/bin/clickhouse
[2024-06-16T12:09:35.377+0000] {docker.py:436} INFO - [0m12:09:35    5. DB::InterpreterInsertQuery::execute() @ 0x0000000010eda99c in /usr/bin/clickhouse
[2024-06-16T12:09:35.377+0000] {docker.py:436} INFO - [0m12:09:35    6. DB::executeQueryImpl(char const*, char const*, std::shared_ptr<DB::Context>, bool, DB::QueryProcessingStage::Enum, DB::ReadBuffer*) @ 0x000000001126305c in /usr/bin/clickhouse
[2024-06-16T12:09:35.378+0000] {docker.py:436} INFO - [0m12:09:35    7. DB::executeQuery(String const&, std::shared_ptr<DB::Context>, bool, DB::QueryProcessingStage::Enum) @ 0x000000001125f86c in /usr/bin/clickhouse
[2024-06-16T12:09:35.378+0000] {docker.py:436} INFO - [0m12:09:35    8. DB::TCPHandler::runImpl() @ 0x0000000011ee42a4 in /usr/bin/clickhouse
[2024-06-16T12:09:35.378+0000] {docker.py:436} INFO - [0m12:09:35    9. DB::TCPHandler::run() @ 0x0000000011ef36a8 in /usr/bin/clickhouse
[2024-06-16T12:09:35.379+0000] {docker.py:436} INFO - [0m12:09:35    10. Poco::Net::TCPServerConnection::start() @ 0x000000001432d0e4 in /usr/bin/clickhouse
[2024-06-16T12:09:35.379+0000] {docker.py:436} INFO - [0m12:09:35    11. Poco::Net::TCPServerDispatcher::run() @ 0x000000001432e600 in /usr/bin/clickhouse
[2024-06-16T12:09:35.379+0000] {docker.py:436} INFO - [0m12:09:35    12. Poco::PooledThread::run() @ 0x000000001446dcfc in /usr/bin/clickhouse
[2024-06-16T12:09:35.380+0000] {docker.py:436} INFO - [0m12:09:35    13. Poco::ThreadImpl::runnableEntry(void*) @ 0x000000001446bea4 in /usr/bin/clickhouse
[2024-06-16T12:09:35.380+0000] {docker.py:436} INFO - [0m12:09:35    14. start_thread @ 0x0000000000007624 in /usr/lib/aarch64-linux-gnu/libpthread-2.31.so
[2024-06-16T12:09:35.380+0000] {docker.py:436} INFO - [0m12:09:35    15. ? @ 0x00000000000d149c in /usr/lib/aarch64-linux-gnu/libc-2.31.so
[2024-06-16T12:09:35.381+0000] {docker.py:436} INFO - [0m12:09:35    compiled Code at target/run/mint/models/example/my_first_dbt_model.sql
[2024-06-16T12:09:35.381+0000] {docker.py:436} INFO - [0m12:09:35
[2024-06-16T12:09:35.382+0000] {docker.py:436} INFO - [0m12:09:35  Done. PASS=0 WARN=0 ERROR=1 SKIP=1 TOTAL=2
[2024-06-16T12:09:36.355+0000] {taskinstance.py:441} INFO - ::group::Post task execution logs
[2024-06-16T12:09:36.368+0000] {taskinstance.py:2905} ERROR - Task failed with exception
Traceback (most recent call last):
  File "/home/airflow/.local/lib/python3.12/site-packages/docker/api/client.py", line 275, in _raise_for_status
    response.raise_for_status()
  File "/home/airflow/.local/lib/python3.12/site-packages/requests/models.py", line 1021, in raise_for_status
    raise HTTPError(http_error_msg, response=self)
requests.exceptions.HTTPError: 400 Client Error: Bad Request for url: http+docker://localhost/v1.45/containers/create

The above exception was the direct cause of the following exception:

Traceback (most recent call last):
  File "/home/airflow/.local/lib/python3.12/site-packages/airflow/providers/docker/operators/docker.py", line 371, in _run_image
    return self._run_image_with_mounts([*self.mounts, tmp_mount], add_tmp_variable=True)
           ^^^^^^^^^^^^^^^^^^^^^^^^^^^^^^^^^^^^^^^^^^^^^^^^^^^^^^^^^^^^^^^^^^^^^^^^^^^^^
  File "/home/airflow/.local/lib/python3.12/site-packages/airflow/providers/docker/operators/docker.py", line 398, in _run_image_with_mounts
    self.container = self.cli.create_container(
                     ^^^^^^^^^^^^^^^^^^^^^^^^^^
  File "/home/airflow/.local/lib/python3.12/site-packages/docker/api/container.py", line 440, in create_container
    return self.create_container_from_config(config, name, platform)
           ^^^^^^^^^^^^^^^^^^^^^^^^^^^^^^^^^^^^^^^^^^^^^^^^^^^^^^^^^
  File "/home/airflow/.local/lib/python3.12/site-packages/docker/api/container.py", line 457, in create_container_from_config
    return self._result(res, True)
           ^^^^^^^^^^^^^^^^^^^^^^^
  File "/home/airflow/.local/lib/python3.12/site-packages/docker/api/client.py", line 281, in _result
    self._raise_for_status(response)
  File "/home/airflow/.local/lib/python3.12/site-packages/docker/api/client.py", line 277, in _raise_for_status
    raise create_api_error_from_http_exception(e) from e
          ^^^^^^^^^^^^^^^^^^^^^^^^^^^^^^^^^^^^^^^
  File "/home/airflow/.local/lib/python3.12/site-packages/docker/errors.py", line 39, in create_api_error_from_http_exception
    raise cls(e, response=response, explanation=explanation) from e
docker.errors.APIError: 400 Client Error for http+docker://localhost/v1.45/containers/create: Bad Request ("invalid mount config for type "bind": bind source path does not exist: /host_mnt/private/tmp/airflowtmpg710s8wr")

During handling of the above exception, another exception occurred:

Traceback (most recent call last):
  File "/home/airflow/.local/lib/python3.12/site-packages/airflow/models/taskinstance.py", line 465, in _execute_task
    result = _execute_callable(context=context, **execute_callable_kwargs)
             ^^^^^^^^^^^^^^^^^^^^^^^^^^^^^^^^^^^^^^^^^^^^^^^^^^^^^^^^^^^^^
  File "/home/airflow/.local/lib/python3.12/site-packages/airflow/models/taskinstance.py", line 432, in _execute_callable
    return execute_callable(context=context, **execute_callable_kwargs)
           ^^^^^^^^^^^^^^^^^^^^^^^^^^^^^^^^^^^^^^^^^^^^^^^^^^^^^^^^^^^^
  File "/home/airflow/.local/lib/python3.12/site-packages/airflow/models/baseoperator.py", line 401, in wrapper
    return func(self, *args, **kwargs)
           ^^^^^^^^^^^^^^^^^^^^^^^^^^^
  File "/home/airflow/.local/lib/python3.12/site-packages/airflow/providers/docker/operators/docker.py", line 509, in execute
    return self._run_image()
           ^^^^^^^^^^^^^^^^^
  File "/home/airflow/.local/lib/python3.12/site-packages/airflow/providers/docker/operators/docker.py", line 380, in _run_image
    return self._run_image_with_mounts(self.mounts, add_tmp_variable=False)
           ^^^^^^^^^^^^^^^^^^^^^^^^^^^^^^^^^^^^^^^^^^^^^^^^^^^^^^^^^^^^^^^^
  File "/home/airflow/.local/lib/python3.12/site-packages/airflow/providers/docker/operators/docker.py", line 444, in _run_image_with_mounts
    raise DockerContainerFailedException(f"Docker container failed: {result!r}", logs=log_lines)
airflow.providers.docker.exceptions.DockerContainerFailedException: Docker container failed: {'StatusCode': 1}
[2024-06-16T12:09:36.377+0000] {taskinstance.py:1206} INFO - Marking task as FAILED. dag_id=full_dbt_execute, task_id=run_dbt, run_id=manual__2024-06-16T12:09:19.592679+00:00, execution_date=20240616T120919, start_date=20240616T120921, end_date=20240616T120936
[2024-06-16T12:09:36.389+0000] {standard_task_runner.py:110} ERROR - Failed to execute job 178 for task run_dbt (Docker container failed: {'StatusCode': 1}; 71)
[2024-06-16T12:09:36.420+0000] {local_task_job_runner.py:240} INFO - Task exited with return code 1
[2024-06-16T12:09:36.444+0000] {taskinstance.py:3503} INFO - 0 downstream tasks scheduled from follow-on schedule check
[2024-06-16T12:09:36.448+0000] {local_task_job_runner.py:222} INFO - ::endgroup::
