[2024-06-16T09:03:37.474+0000] {local_task_job_runner.py:120} INFO - ::group::Pre task execution logs
[2024-06-16T09:03:37.492+0000] {taskinstance.py:2076} INFO - Dependencies all met for dep_context=non-requeueable deps ti=<TaskInstance: full_dbt_execute.run_dbt manual__2024-06-16T09:03:35.832992+00:00 [queued]>
[2024-06-16T09:03:37.496+0000] {taskinstance.py:2076} INFO - Dependencies all met for dep_context=requeueable deps ti=<TaskInstance: full_dbt_execute.run_dbt manual__2024-06-16T09:03:35.832992+00:00 [queued]>
[2024-06-16T09:03:37.496+0000] {taskinstance.py:2306} INFO - Starting attempt 1 of 1
[2024-06-16T09:03:37.503+0000] {taskinstance.py:2330} INFO - Executing <Task(DockerOperator): run_dbt> on 2024-06-16 09:03:35.832992+00:00
[2024-06-16T09:03:37.509+0000] {warnings.py:112} WARNING - /home/***/.local/lib/python3.12/site-packages/***/task/task_runner/standard_task_runner.py:61: DeprecationWarning: This process (pid=49) is multi-threaded, use of fork() may lead to deadlocks in the child.
  pid = os.fork()

[2024-06-16T09:03:37.511+0000] {standard_task_runner.py:63} INFO - Started process 51 to run task
[2024-06-16T09:03:37.510+0000] {standard_task_runner.py:90} INFO - Running: ['***', 'tasks', 'run', 'full_dbt_execute', 'run_dbt', 'manual__2024-06-16T09:03:35.832992+00:00', '--job-id', '137', '--raw', '--subdir', 'DAGS_FOLDER/full_dbt_execute.py', '--cfg-path', '/tmp/tmpdgcq_6xo']
[2024-06-16T09:03:37.513+0000] {standard_task_runner.py:91} INFO - Job 137: Subtask run_dbt
[2024-06-16T09:03:37.546+0000] {task_command.py:426} INFO - Running <TaskInstance: full_dbt_execute.run_dbt manual__2024-06-16T09:03:35.832992+00:00 [running]> on host a1b8253dd4b8
[2024-06-16T09:03:37.599+0000] {taskinstance.py:2648} INFO - Exporting env vars: AIRFLOW_CTX_DAG_OWNER='***' AIRFLOW_CTX_DAG_ID='full_dbt_execute' AIRFLOW_CTX_TASK_ID='run_dbt' AIRFLOW_CTX_EXECUTION_DATE='2024-06-16T09:03:35.832992+00:00' AIRFLOW_CTX_TRY_NUMBER='1' AIRFLOW_CTX_DAG_RUN_ID='manual__2024-06-16T09:03:35.832992+00:00'
[2024-06-16T09:03:37.601+0000] {taskinstance.py:430} INFO - ::endgroup::
[2024-06-16T09:03:37.643+0000] {docker.py:366} INFO - Starting docker container from image custom_dbt_image
[2024-06-16T09:03:37.663+0000] {docker.py:374} WARNING - Using remote engine or docker-in-docker and mounting temporary volume from host is not supported. Falling back to `mount_tmp_dir=False` mode. You can set `mount_tmp_dir` parameter to False to disable mounting and remove the warning
[2024-06-16T09:03:39.992+0000] {docker.py:436} INFO - [0m09:03:39  Running with dbt=1.5.0
[2024-06-16T09:03:40.096+0000] {docker.py:436} INFO - [0m09:03:40  Unable to do partial parsing because profile has changed
[2024-06-16T09:03:40.670+0000] {docker.py:436} INFO - [0m09:03:40  Found 2 models, 4 tests, 0 snapshots, 0 analyses, 341 macros, 0 operations, 0 seed files, 0 sources, 0 exposures, 0 metrics, 0 groups
[2024-06-16T09:03:40.672+0000] {docker.py:436} INFO - [0m09:03:40
[2024-06-16T09:03:46.008+0000] {docker.py:436} INFO - [0m09:03:46  dbt_clickhouse adapter: Failed to run exchange test
[2024-06-16T09:03:46.117+0000] {docker.py:436} INFO - [0m09:03:46  Concurrency: 1 threads (target='dev')
[2024-06-16T09:03:46.120+0000] {docker.py:436} INFO - [0m09:03:46
[2024-06-16T09:03:46.143+0000] {docker.py:436} INFO - [0m09:03:46  1 of 2 START sql table model mint.my_first_dbt_model ........................... [RUN]
[2024-06-16T09:03:46.225+0000] {docker.py:436} INFO - [0m09:03:46  1 of 2 ERROR creating sql table model mint.my_first_dbt_model .................. [[31mERROR[0m in 0.08s]
[2024-06-16T09:03:46.227+0000] {docker.py:436} INFO - [0m09:03:46  2 of 2 SKIP relation mint.my_second_dbt_model .................................. [[33mSKIP[0m]
[2024-06-16T09:03:46.240+0000] {docker.py:436} INFO - [0m09:03:46
[2024-06-16T09:03:46.240+0000] {docker.py:436} INFO - [0m09:03:46  Finished running 1 table model, 1 view model in 0 hours 0 minutes and 5.57 seconds (5.57s).
[2024-06-16T09:03:46.250+0000] {docker.py:436} INFO - [0m09:03:46
[2024-06-16T09:03:46.251+0000] {docker.py:436} INFO - [0m09:03:46  [31mCompleted with 1 error and 0 warnings:[0m
[2024-06-16T09:03:46.251+0000] {docker.py:436} INFO - [0m09:03:46
[2024-06-16T09:03:46.252+0000] {docker.py:436} INFO - [0m09:03:46  [33mDatabase Error in model my_first_dbt_model (models/example/my_first_dbt_model.sql)[0m
[2024-06-16T09:03:46.252+0000] {docker.py:436} INFO - [0m09:03:46    Code: 62.
[2024-06-16T09:03:46.252+0000] {docker.py:436} INFO - [0m09:03:46    DB::Exception: Syntax error: failed at position 338 ('(') (line 17, col 15): ( /*
[2024-06-16T09:03:46.253+0000] {docker.py:436} INFO - [0m09:03:46        Welcome to your first dbt model!
[2024-06-16T09:03:46.253+0000] {docker.py:436} INFO - [0m09:03:46        Did you know that you can also configure models directly within SQL files?
[2024-06-16T09:03:46.254+0000] {docker.py:436} INFO - [0m09:03:46        This will override configurations s. Unmatched parentheses: (. Stack trace:
[2024-06-16T09:03:46.254+0000] {docker.py:436} INFO - [0m09:03:46
[2024-06-16T09:03:46.254+0000] {docker.py:436} INFO - [0m09:03:46    0. DB::Exception::Exception(DB::Exception::MessageMasked&&, int, bool) @ 0x000000000c01d464 in /usr/bin/clickhouse
[2024-06-16T09:03:46.255+0000] {docker.py:436} INFO - [0m09:03:46    1. DB::Exception::createDeprecated(String const&, int, bool) @ 0x0000000007a5c5e0 in /usr/bin/clickhouse
[2024-06-16T09:03:46.255+0000] {docker.py:436} INFO - [0m09:03:46    2. DB::parseQueryAndMovePosition(DB::IParser&, char const*&, char const*, String const&, bool, unsigned long, unsigned long) @ 0x00000000125e7718 in /usr/bin/clickhouse
[2024-06-16T09:03:46.255+0000] {docker.py:436} INFO - [0m09:03:46    3. DB::executeQueryImpl(char const*, char const*, std::shared_ptr<DB::Context>, bool, DB::QueryProcessingStage::Enum, DB::ReadBuffer*) @ 0x00000000112601f0 in /usr/bin/clickhouse
[2024-06-16T09:03:46.256+0000] {docker.py:436} INFO - [0m09:03:46    4. DB::executeQuery(String const&, std::shared_ptr<DB::Context>, bool, DB::QueryProcessingStage::Enum) @ 0x000000001125f86c in /usr/bin/clickhouse
[2024-06-16T09:03:46.256+0000] {docker.py:436} INFO - [0m09:03:46    5. DB::TCPHandler::runImpl() @ 0x0000000011ee42a4 in /usr/bin/clickhouse
[2024-06-16T09:03:46.257+0000] {docker.py:436} INFO - [0m09:03:46    6. DB::TCPHandler::run() @ 0x0000000011ef36a8 in /usr/bin/clickhouse
[2024-06-16T09:03:46.257+0000] {docker.py:436} INFO - [0m09:03:46    7. Poco::Net::TCPServerConnection::start() @ 0x000000001432d0e4 in /usr/bin/clickhouse
[2024-06-16T09:03:46.258+0000] {docker.py:436} INFO - [0m09:03:46    8. Poco::Net::TCPServerDispatcher::run() @ 0x000000001432e600 in /usr/bin/clickhouse
[2024-06-16T09:03:46.258+0000] {docker.py:436} INFO - [0m09:03:46    9. Poco::PooledThread::run() @ 0x000000001446dcfc in /usr/bin/clickhouse
[2024-06-16T09:03:46.259+0000] {docker.py:436} INFO - [0m09:03:46    10. Poco::ThreadImpl::runnableEntry(void*) @ 0x000000001446bea4 in /usr/bin/clickhouse
[2024-06-16T09:03:46.260+0000] {docker.py:436} INFO - [0m09:03:46    11. start_thread @ 0x0000000000007624 in /usr/lib/aarch64-linux-gnu/libpthread-2.31.so
[2024-06-16T09:03:46.261+0000] {docker.py:436} INFO - [0m09:03:46    12. ? @ 0x00000000000d149c in /usr/lib/aarch64-linux-gnu/libc-2.31.so
[2024-06-16T09:03:46.261+0000] {docker.py:436} INFO - [0m09:03:46
[2024-06-16T09:03:46.262+0000] {docker.py:436} INFO - [0m09:03:46  Done. PASS=0 WARN=0 ERROR=1 SKIP=1 TOTAL=2
[2024-06-16T09:03:47.602+0000] {taskinstance.py:441} INFO - ::group::Post task execution logs
[2024-06-16T09:03:47.628+0000] {taskinstance.py:2905} ERROR - Task failed with exception
Traceback (most recent call last):
  File "/home/airflow/.local/lib/python3.12/site-packages/docker/api/client.py", line 275, in _raise_for_status
    response.raise_for_status()
  File "/home/airflow/.local/lib/python3.12/site-packages/requests/models.py", line 1021, in raise_for_status
    raise HTTPError(http_error_msg, response=self)
requests.exceptions.HTTPError: 400 Client Error: Bad Request for url: http+docker://localhost/v1.45/containers/create

The above exception was the direct cause of the following exception:

Traceback (most recent call last):
  File "/home/airflow/.local/lib/python3.12/site-packages/airflow/providers/docker/operators/docker.py", line 371, in _run_image
    return self._run_image_with_mounts([*self.mounts, tmp_mount], add_tmp_variable=True)
           ^^^^^^^^^^^^^^^^^^^^^^^^^^^^^^^^^^^^^^^^^^^^^^^^^^^^^^^^^^^^^^^^^^^^^^^^^^^^^
  File "/home/airflow/.local/lib/python3.12/site-packages/airflow/providers/docker/operators/docker.py", line 398, in _run_image_with_mounts
    self.container = self.cli.create_container(
                     ^^^^^^^^^^^^^^^^^^^^^^^^^^
  File "/home/airflow/.local/lib/python3.12/site-packages/docker/api/container.py", line 440, in create_container
    return self.create_container_from_config(config, name, platform)
           ^^^^^^^^^^^^^^^^^^^^^^^^^^^^^^^^^^^^^^^^^^^^^^^^^^^^^^^^^
  File "/home/airflow/.local/lib/python3.12/site-packages/docker/api/container.py", line 457, in create_container_from_config
    return self._result(res, True)
           ^^^^^^^^^^^^^^^^^^^^^^^
  File "/home/airflow/.local/lib/python3.12/site-packages/docker/api/client.py", line 281, in _result
    self._raise_for_status(response)
  File "/home/airflow/.local/lib/python3.12/site-packages/docker/api/client.py", line 277, in _raise_for_status
    raise create_api_error_from_http_exception(e) from e
          ^^^^^^^^^^^^^^^^^^^^^^^^^^^^^^^^^^^^^^^
  File "/home/airflow/.local/lib/python3.12/site-packages/docker/errors.py", line 39, in create_api_error_from_http_exception
    raise cls(e, response=response, explanation=explanation) from e
docker.errors.APIError: 400 Client Error for http+docker://localhost/v1.45/containers/create: Bad Request ("invalid mount config for type "bind": bind source path does not exist: /host_mnt/private/tmp/airflowtmpkd7br1ao")

During handling of the above exception, another exception occurred:

Traceback (most recent call last):
  File "/home/airflow/.local/lib/python3.12/site-packages/airflow/models/taskinstance.py", line 465, in _execute_task
    result = _execute_callable(context=context, **execute_callable_kwargs)
             ^^^^^^^^^^^^^^^^^^^^^^^^^^^^^^^^^^^^^^^^^^^^^^^^^^^^^^^^^^^^^
  File "/home/airflow/.local/lib/python3.12/site-packages/airflow/models/taskinstance.py", line 432, in _execute_callable
    return execute_callable(context=context, **execute_callable_kwargs)
           ^^^^^^^^^^^^^^^^^^^^^^^^^^^^^^^^^^^^^^^^^^^^^^^^^^^^^^^^^^^^
  File "/home/airflow/.local/lib/python3.12/site-packages/airflow/models/baseoperator.py", line 401, in wrapper
    return func(self, *args, **kwargs)
           ^^^^^^^^^^^^^^^^^^^^^^^^^^^
  File "/home/airflow/.local/lib/python3.12/site-packages/airflow/providers/docker/operators/docker.py", line 509, in execute
    return self._run_image()
           ^^^^^^^^^^^^^^^^^
  File "/home/airflow/.local/lib/python3.12/site-packages/airflow/providers/docker/operators/docker.py", line 380, in _run_image
    return self._run_image_with_mounts(self.mounts, add_tmp_variable=False)
           ^^^^^^^^^^^^^^^^^^^^^^^^^^^^^^^^^^^^^^^^^^^^^^^^^^^^^^^^^^^^^^^^
  File "/home/airflow/.local/lib/python3.12/site-packages/airflow/providers/docker/operators/docker.py", line 444, in _run_image_with_mounts
    raise DockerContainerFailedException(f"Docker container failed: {result!r}", logs=log_lines)
airflow.providers.docker.exceptions.DockerContainerFailedException: Docker container failed: {'StatusCode': 1}
[2024-06-16T09:03:47.640+0000] {taskinstance.py:1206} INFO - Marking task as FAILED. dag_id=full_dbt_execute, task_id=run_dbt, run_id=manual__2024-06-16T09:03:35.832992+00:00, execution_date=20240616T090335, start_date=20240616T090337, end_date=20240616T090347
[2024-06-16T09:03:47.672+0000] {standard_task_runner.py:110} ERROR - Failed to execute job 137 for task run_dbt (Docker container failed: {'StatusCode': 1}; 51)
[2024-06-16T09:03:47.694+0000] {local_task_job_runner.py:240} INFO - Task exited with return code 1
[2024-06-16T09:03:47.723+0000] {taskinstance.py:3503} INFO - 0 downstream tasks scheduled from follow-on schedule check
[2024-06-16T09:03:47.726+0000] {local_task_job_runner.py:222} INFO - ::endgroup::
