[2024-06-17T16:26:33.422+0000] {local_task_job_runner.py:120} INFO - ::group::Pre task execution logs
[2024-06-17T16:26:33.434+0000] {taskinstance.py:2076} INFO - Dependencies all met for dep_context=non-requeueable deps ti=<TaskInstance: full_dbt_execute.run_dbt manual__2024-06-17T16:26:31.668382+00:00 [queued]>
[2024-06-17T16:26:33.437+0000] {taskinstance.py:2076} INFO - Dependencies all met for dep_context=requeueable deps ti=<TaskInstance: full_dbt_execute.run_dbt manual__2024-06-17T16:26:31.668382+00:00 [queued]>
[2024-06-17T16:26:33.437+0000] {taskinstance.py:2306} INFO - Starting attempt 1 of 1
[2024-06-17T16:26:33.443+0000] {taskinstance.py:2330} INFO - Executing <Task(DockerOperator): run_dbt> on 2024-06-17 16:26:31.668382+00:00
[2024-06-17T16:26:33.448+0000] {warnings.py:112} WARNING - /home/***/.local/lib/python3.12/site-packages/***/task/task_runner/standard_task_runner.py:61: DeprecationWarning: This process (pid=123) is multi-threaded, use of fork() may lead to deadlocks in the child.
  pid = os.fork()

[2024-06-17T16:26:33.449+0000] {standard_task_runner.py:63} INFO - Started process 125 to run task
[2024-06-17T16:26:33.449+0000] {standard_task_runner.py:90} INFO - Running: ['***', 'tasks', 'run', 'full_dbt_execute', 'run_dbt', 'manual__2024-06-17T16:26:31.668382+00:00', '--job-id', '202', '--raw', '--subdir', 'DAGS_FOLDER/full_dbt_execute.py', '--cfg-path', '/tmp/tmpd9gcarm8']
[2024-06-17T16:26:33.451+0000] {standard_task_runner.py:91} INFO - Job 202: Subtask run_dbt
[2024-06-17T16:26:33.477+0000] {task_command.py:426} INFO - Running <TaskInstance: full_dbt_execute.run_dbt manual__2024-06-17T16:26:31.668382+00:00 [running]> on host a1b8253dd4b8
[2024-06-17T16:26:33.532+0000] {taskinstance.py:2648} INFO - Exporting env vars: AIRFLOW_CTX_DAG_OWNER='***' AIRFLOW_CTX_DAG_ID='full_dbt_execute' AIRFLOW_CTX_TASK_ID='run_dbt' AIRFLOW_CTX_EXECUTION_DATE='2024-06-17T16:26:31.668382+00:00' AIRFLOW_CTX_TRY_NUMBER='1' AIRFLOW_CTX_DAG_RUN_ID='manual__2024-06-17T16:26:31.668382+00:00'
[2024-06-17T16:26:33.537+0000] {taskinstance.py:430} INFO - ::endgroup::
[2024-06-17T16:26:33.625+0000] {docker.py:366} INFO - Starting docker container from image custom_dbt_image
[2024-06-17T16:26:33.632+0000] {docker.py:374} WARNING - Using remote engine or docker-in-docker and mounting temporary volume from host is not supported. Falling back to `mount_tmp_dir=False` mode. You can set `mount_tmp_dir` parameter to False to disable mounting and remove the warning
[2024-06-17T16:26:33.808+0000] {taskinstance.py:441} INFO - ::group::Post task execution logs
[2024-06-17T16:26:33.811+0000] {taskinstance.py:2905} ERROR - Task failed with exception
Traceback (most recent call last):
  File "/home/airflow/.local/lib/python3.12/site-packages/docker/api/client.py", line 275, in _raise_for_status
    response.raise_for_status()
  File "/home/airflow/.local/lib/python3.12/site-packages/requests/models.py", line 1021, in raise_for_status
    raise HTTPError(http_error_msg, response=self)
requests.exceptions.HTTPError: 400 Client Error: Bad Request for url: http+docker://localhost/v1.45/containers/create

The above exception was the direct cause of the following exception:

Traceback (most recent call last):
  File "/home/airflow/.local/lib/python3.12/site-packages/airflow/providers/docker/operators/docker.py", line 371, in _run_image
    return self._run_image_with_mounts([*self.mounts, tmp_mount], add_tmp_variable=True)
           ^^^^^^^^^^^^^^^^^^^^^^^^^^^^^^^^^^^^^^^^^^^^^^^^^^^^^^^^^^^^^^^^^^^^^^^^^^^^^
  File "/home/airflow/.local/lib/python3.12/site-packages/airflow/providers/docker/operators/docker.py", line 398, in _run_image_with_mounts
    self.container = self.cli.create_container(
                     ^^^^^^^^^^^^^^^^^^^^^^^^^^
  File "/home/airflow/.local/lib/python3.12/site-packages/docker/api/container.py", line 440, in create_container
    return self.create_container_from_config(config, name, platform)
           ^^^^^^^^^^^^^^^^^^^^^^^^^^^^^^^^^^^^^^^^^^^^^^^^^^^^^^^^^
  File "/home/airflow/.local/lib/python3.12/site-packages/docker/api/container.py", line 457, in create_container_from_config
    return self._result(res, True)
           ^^^^^^^^^^^^^^^^^^^^^^^
  File "/home/airflow/.local/lib/python3.12/site-packages/docker/api/client.py", line 281, in _result
    self._raise_for_status(response)
  File "/home/airflow/.local/lib/python3.12/site-packages/docker/api/client.py", line 277, in _raise_for_status
    raise create_api_error_from_http_exception(e) from e
          ^^^^^^^^^^^^^^^^^^^^^^^^^^^^^^^^^^^^^^^
  File "/home/airflow/.local/lib/python3.12/site-packages/docker/errors.py", line 39, in create_api_error_from_http_exception
    raise cls(e, response=response, explanation=explanation) from e
docker.errors.APIError: 400 Client Error for http+docker://localhost/v1.45/containers/create: Bad Request ("invalid mount config for type "bind": bind source path does not exist: /host_mnt/private/tmp/airflowtmpcmh1rhuj")

During handling of the above exception, another exception occurred:

Traceback (most recent call last):
  File "/home/airflow/.local/lib/python3.12/site-packages/docker/api/client.py", line 275, in _raise_for_status
    response.raise_for_status()
  File "/home/airflow/.local/lib/python3.12/site-packages/requests/models.py", line 1021, in raise_for_status
    raise HTTPError(http_error_msg, response=self)
requests.exceptions.HTTPError: 409 Client Error: Conflict for url: http+docker://localhost/v1.45/containers/80128b5efa20baaad34ee0f69d8533610d1b320518c5fa432f579a7a810d9485/start

The above exception was the direct cause of the following exception:

Traceback (most recent call last):
  File "/home/airflow/.local/lib/python3.12/site-packages/airflow/models/taskinstance.py", line 465, in _execute_task
    result = _execute_callable(context=context, **execute_callable_kwargs)
             ^^^^^^^^^^^^^^^^^^^^^^^^^^^^^^^^^^^^^^^^^^^^^^^^^^^^^^^^^^^^^
  File "/home/airflow/.local/lib/python3.12/site-packages/airflow/models/taskinstance.py", line 432, in _execute_callable
    return execute_callable(context=context, **execute_callable_kwargs)
           ^^^^^^^^^^^^^^^^^^^^^^^^^^^^^^^^^^^^^^^^^^^^^^^^^^^^^^^^^^^^
  File "/home/airflow/.local/lib/python3.12/site-packages/airflow/models/baseoperator.py", line 401, in wrapper
    return func(self, *args, **kwargs)
           ^^^^^^^^^^^^^^^^^^^^^^^^^^^
  File "/home/airflow/.local/lib/python3.12/site-packages/airflow/providers/docker/operators/docker.py", line 509, in execute
    return self._run_image()
           ^^^^^^^^^^^^^^^^^
  File "/home/airflow/.local/lib/python3.12/site-packages/airflow/providers/docker/operators/docker.py", line 380, in _run_image
    return self._run_image_with_mounts(self.mounts, add_tmp_variable=False)
           ^^^^^^^^^^^^^^^^^^^^^^^^^^^^^^^^^^^^^^^^^^^^^^^^^^^^^^^^^^^^^^^^
  File "/home/airflow/.local/lib/python3.12/site-packages/airflow/providers/docker/operators/docker.py", line 430, in _run_image_with_mounts
    self.cli.start(self.container["Id"])
  File "/home/airflow/.local/lib/python3.12/site-packages/docker/utils/decorators.py", line 19, in wrapped
    return f(self, resource_id, *args, **kwargs)
           ^^^^^^^^^^^^^^^^^^^^^^^^^^^^^^^^^^^^^
  File "/home/airflow/.local/lib/python3.12/site-packages/docker/api/container.py", line 1136, in start
    self._raise_for_status(res)
  File "/home/airflow/.local/lib/python3.12/site-packages/docker/api/client.py", line 277, in _raise_for_status
    raise create_api_error_from_http_exception(e) from e
          ^^^^^^^^^^^^^^^^^^^^^^^^^^^^^^^^^^^^^^^
  File "/home/airflow/.local/lib/python3.12/site-packages/docker/errors.py", line 39, in create_api_error_from_http_exception
    raise cls(e, response=response, explanation=explanation) from e
docker.errors.APIError: 409 Client Error for http+docker://localhost/v1.45/containers/80128b5efa20baaad34ee0f69d8533610d1b320518c5fa432f579a7a810d9485/start: Conflict ("cannot join network of a non running container: b33aad17c9a34c9f80279cddaf3782742b995064baa5ac673109ba0517393a02")
[2024-06-17T16:26:33.828+0000] {taskinstance.py:1206} INFO - Marking task as FAILED. dag_id=full_dbt_execute, task_id=run_dbt, run_id=manual__2024-06-17T16:26:31.668382+00:00, execution_date=20240617T162631, start_date=20240617T162633, end_date=20240617T162633
[2024-06-17T16:26:33.843+0000] {standard_task_runner.py:110} ERROR - Failed to execute job 202 for task run_dbt (409 Client Error for http+docker://localhost/v1.45/containers/80128b5efa20baaad34ee0f69d8533610d1b320518c5fa432f579a7a810d9485/start: Conflict ("cannot join network of a non running container: b33aad17c9a34c9f80279cddaf3782742b995064baa5ac673109ba0517393a02"); 125)
[2024-06-17T16:26:33.880+0000] {local_task_job_runner.py:240} INFO - Task exited with return code 1
[2024-06-17T16:26:33.901+0000] {taskinstance.py:3503} INFO - 0 downstream tasks scheduled from follow-on schedule check
[2024-06-17T16:26:33.904+0000] {local_task_job_runner.py:222} INFO - ::endgroup::
